<?xml version="1.0" encoding="UTF-8"?>
<testng-results ignored="9" total="10" passed="0" failed="1" skipped="0">
  <reporter-output>
  </reporter-output>
  <suite started-at="2024-12-06T12:49:51 IST" name="Default suite" finished-at="2024-12-06T12:49:51 IST" duration-ms="62">
    <groups>
    </groups>
    <test started-at="2024-12-06T12:49:51 IST" name="Default test" finished-at="2024-12-06T12:49:51 IST" duration-ms="62">
      <class name="TestNG.HardAssertEx">
        <test-method signature="m10()[pri:0, instance:TestNG.HardAssertEx@1b11171f]" started-at="2024-12-06T12:49:51 IST" name="m10" finished-at="2024-12-06T12:49:51 IST" duration-ms="18" status="FAIL">
          <exception class="java.lang.AssertionError">
            <message>
              <![CDATA[same expected [hello] but found [hell]]]>
            </message>
            <full-stacktrace>
              <![CDATA[java.lang.AssertionError: same expected [hello] but found [hell]
at org.testng.Assert.fail(Assert.java:99)
at org.testng.Assert.failNotSame(Assert.java:1033)
at org.testng.Assert.assertSame(Assert.java:981)
at TestNG.HardAssertEx.m10(HardAssertEx.java:83)
at java.base/jdk.internal.reflect.DirectMethodHandleAccessor.invoke(DirectMethodHandleAccessor.java:103)
at java.base/java.lang.reflect.Method.invoke(Method.java:580)
at org.testng.internal.MethodInvocationHelper.invokeMethod(MethodInvocationHelper.java:133)
at org.testng.internal.TestInvoker.invokeMethod(TestInvoker.java:598)
at org.testng.internal.TestInvoker.invokeTestMethod(TestInvoker.java:173)
at org.testng.internal.MethodRunner.runInSequence(MethodRunner.java:46)
at org.testng.internal.TestInvoker$MethodInvocationAgent.invoke(TestInvoker.java:824)
at org.testng.internal.TestInvoker.invokeTestMethods(TestInvoker.java:146)
at org.testng.internal.TestMethodWorker.invokeTestMethods(TestMethodWorker.java:146)
at org.testng.internal.TestMethodWorker.run(TestMethodWorker.java:128)
at java.base/java.util.ArrayList.forEach(ArrayList.java:1597)
at org.testng.TestRunner.privateRun(TestRunner.java:794)
at org.testng.TestRunner.run(TestRunner.java:596)
at org.testng.SuiteRunner.runTest(SuiteRunner.java:377)
at org.testng.SuiteRunner.runSequentially(SuiteRunner.java:371)
at org.testng.SuiteRunner.privateRun(SuiteRunner.java:332)
at org.testng.SuiteRunner.run(SuiteRunner.java:276)
at org.testng.SuiteRunnerWorker.runSuite(SuiteRunnerWorker.java:53)
at org.testng.SuiteRunnerWorker.run(SuiteRunnerWorker.java:96)
at org.testng.TestNG.runSuitesSequentially(TestNG.java:1212)
at org.testng.TestNG.runSuitesLocally(TestNG.java:1134)
at org.testng.TestNG.runSuites(TestNG.java:1063)
at org.testng.TestNG.run(TestNG.java:1031)
at org.testng.remote.AbstractRemoteTestNG.run(AbstractRemoteTestNG.java:115)
at org.testng.remote.RemoteTestNG.initAndRun(RemoteTestNG.java:293)
at org.testng.remote.RemoteTestNG.main(RemoteTestNG.java:91)
]]>
            </full-stacktrace>
          </exception> <!-- java.lang.AssertionError -->
          <reporter-output>
          </reporter-output>
        </test-method> <!-- m10 -->
      </class> <!-- TestNG.HardAssertEx -->
    </test> <!-- Default test -->
  </suite> <!-- Default suite -->
</testng-results>
