<?xml version="1.0" encoding="UTF-8"?>
<!-- Generated by org.testng.reporters.JUnitXMLReporter -->
<testsuite ignored="9" hostname="Keerthi" failures="1" tests="1" name="Default test" time="0.062" errors="0" timestamp="2024-12-06T12:49:51 IST">
  <testcase classname="TestNG.HardAssertEx" name="m10" time="0.018">
    <failure type="java.lang.AssertionError" message="same expected [hello] but found [hell]">
      <![CDATA[java.lang.AssertionError: same expected [hello] but found [hell]
at org.testng.Assert.fail(Assert.java:99)
at org.testng.Assert.failNotSame(Assert.java:1033)
at org.testng.Assert.assertSame(Assert.java:981)
at TestNG.HardAssertEx.m10(HardAssertEx.java:83)
at java.base/jdk.internal.reflect.DirectMethodHandleAccessor.invoke(DirectMethodHandleAccessor.java:103)
at java.base/java.lang.reflect.Method.invoke(Method.java:580)
at org.testng.internal.MethodInvocationHelper.invokeMethod(MethodInvocationHelper.java:133)
at org.testng.internal.TestInvoker.invokeMethod(TestInvoker.java:598)
at org.testng.internal.TestInvoker.invokeTestMethod(TestInvoker.java:173)
at org.testng.internal.MethodRunner.runInSequence(MethodRunner.java:46)
at org.testng.internal.TestInvoker$MethodInvocationAgent.invoke(TestInvoker.java:824)
at org.testng.internal.TestInvoker.invokeTestMethods(TestInvoker.java:146)
at org.testng.internal.TestMethodWorker.invokeTestMethods(TestMethodWorker.java:146)
at org.testng.internal.TestMethodWorker.run(TestMethodWorker.java:128)
at java.base/java.util.ArrayList.forEach(ArrayList.java:1597)
at org.testng.TestRunner.privateRun(TestRunner.java:794)
at org.testng.TestRunner.run(TestRunner.java:596)
at org.testng.SuiteRunner.runTest(SuiteRunner.java:377)
at org.testng.SuiteRunner.runSequentially(SuiteRunner.java:371)
at org.testng.SuiteRunner.privateRun(SuiteRunner.java:332)
at org.testng.SuiteRunner.run(SuiteRunner.java:276)
at org.testng.SuiteRunnerWorker.runSuite(SuiteRunnerWorker.java:53)
at org.testng.SuiteRunnerWorker.run(SuiteRunnerWorker.java:96)
at org.testng.TestNG.runSuitesSequentially(TestNG.java:1212)
at org.testng.TestNG.runSuitesLocally(TestNG.java:1134)
at org.testng.TestNG.runSuites(TestNG.java:1063)
at org.testng.TestNG.run(TestNG.java:1031)
at org.testng.remote.AbstractRemoteTestNG.run(AbstractRemoteTestNG.java:115)
at org.testng.remote.RemoteTestNG.initAndRun(RemoteTestNG.java:293)
at org.testng.remote.RemoteTestNG.main(RemoteTestNG.java:91)
]]>
    </failure>
  </testcase> <!-- m10 -->
  <testcase classname="TestNG.HardAssertEx" name="m4" time="0.0">
    <ignored/>
  </testcase> <!-- m4 -->
  <testcase classname="TestNG.HardAssertEx" name="m5" time="0.0">
    <ignored/>
  </testcase> <!-- m5 -->
  <testcase classname="TestNG.HardAssertEx" name="m6" time="0.0">
    <ignored/>
  </testcase> <!-- m6 -->
  <testcase classname="TestNG.HardAssertEx" name="m7" time="0.0">
    <ignored/>
  </testcase> <!-- m7 -->
  <testcase classname="TestNG.HardAssertEx" name="m8" time="0.0">
    <ignored/>
  </testcase> <!-- m8 -->
  <testcase classname="TestNG.HardAssertEx" name="m9" time="0.0">
    <ignored/>
  </testcase> <!-- m9 -->
  <testcase classname="TestNG.HardAssertEx" name="m1" time="0.0">
    <ignored/>
  </testcase> <!-- m1 -->
  <testcase classname="TestNG.HardAssertEx" name="m2" time="0.0">
    <ignored/>
  </testcase> <!-- m2 -->
  <testcase classname="TestNG.HardAssertEx" name="m3" time="0.0">
    <ignored/>
  </testcase> <!-- m3 -->
</testsuite> <!-- Default test -->
